Workbook
Name _ftn1: Beschikbaarheid!$B$34
Name _ftnref1: Algemeen!#REF!
Name _Toc367866010: Algemeen!$A$43
Name besalt: Waarderingstabellen!$Q$4
Name besalt1: Waarderingstabellen!$Q$4:$Q$5
Name beschikbaarheid: Waarderingstabellen!$O$4:$O$9
Name beschikbaarheid: Waarderingstabellen!$O$4:$O$9
Name Integriteit: [1]waarderingstabellen!$O$12:$O$17
Name Integriteit: Waarderingstabellen!$O$12:$O$17
Name keuzep2: [1]waarderingstabellen!$Q$29:$Q$30
Name keuzep2: Waarderingstabellen!$Q$29:$Q$30
Name privacy: [1]waarderingstabellen!$O$29:$O$32
Name privacy: Waarderingstabellen!$O$29:$O$32
Name Vertrouwelijkheid: [1]waarderingstabellen!$O$21:$O$26
Name Vertrouwelijkheid: Waarderingstabellen!$O$21:$O$26

Sheet Algemeen
A1: Classificatietoets BIO2 gemeenten
A3: 1.1 Waarom classificeren:
A4: Voorliggende handreiking beschrijft een good practice voor classificatie van informatie.
A5: Het belang van classificeren is een inzicht krijgen in de waarde van informatie over de assen beschikbaarheid, integriteit en vertrouwelijkheid. Als dat inzicht er is kan men passende maatregelen nemen om die informatie te beschermen. Voor gemeenten zijn dat de maatregelen uit de BIO2 en eventueel de aanvullende gemeentelijke set van maatregelen. De voorgestelde classificatiemethodiek geeft een snelle indicatie van het belang van de informatie die verwerkt wordt in informatiesystemen en is daarmee een basis voor de maatregelselectie of een aanvullende risicoanalyse. De Cbw spreekt ook nog over authenticiteit en dat zat al in de integriteits vragen, en maakt dus een integraal onderdeel uit van de toets.
A6: Deze dataclassificatietoets BIO2 is een hulpmiddel om vast te kunnen stellen welke classificatie informatie heeft die binnen een gemeentelijk proces gebruikt wordt. Deze dataclassificatietoets BIO2 is niet verplicht, maar kan helpen als er toch twijfels zijn of bepaalde informatie die binnen een gemeentelijk proces gebruikt wordt te classificeren en zo ook de mogelijkheid te creëren dat de juiste beschermingsmaatregelen gebruikt gaan worden. Deze dataclassificatie kan op 2 manieren worden toegepast:
A7: 1. Om de waarde van de informatie te bepalen, op basis van de criteria in deze tool. Op basis van de classificatie van informatie kunnen nadere beveiligings/beschermingsmaatregelen beveiligingsmaatregelen worden toegepast. Hier bestaan zelfs al kaders voor (ABDO/ABRO) die ook voor gemeenten goed zijn om naar te kijken, eventueel voorafgegaan door een aanvullende risicoanalyse.
A8: 2. Om in de fase tijdens het starten van een project of voor een nieuw informatiesysteem, de dataclassificatietoets BIO2 op te laten stellen door de proces verantwoordelijke. Het resultaat kan dan leiden tot het eventueel nemen van extra beveiligingsmaatregelen of het uitvoeren van een risicoanalyse.
A10: Het toekennen van classificatieniveaus aan informatie is belangrijk, omdat daarmee het (vereiste) beschermingsniveau kenbaar gemaakt wordt. Aan de hand hiervan kan worden bepaald welke beveiligingseisen gelden en welke maatregelen moeten worden genomen. Dit is bijvoorbeeld relevant voor beheerders die lang niet altijd bekend zijn met de inhoud en dus de waarde van informatie, maar wel worden geacht adequate beschermingsmaatregelen te treffen. De volgende factoren oefenen invloed uit op de adequate beveiligingsmaatregelen: - wet- en regelgeving, - beleidsuitgangspunten, - architectuurprincipes, - BIV-classificatieniveau, - dreigingsprofiel en het basisbeveiligingsniveau. Het resultaat van deze dataclassificatietoets BIO2 kan duiden op een zwaartepunt in het te beschermen belang. Er is bijvoorbeeld een hogere score voor beschikbaarheid, maar niet op integriteit en vertrouwelijkheid. In de daarna uit te voeren risicoanalyse dient dan de nadruk te liggen op verhogen van dat belang, in dit voorbeeld de beschikbaarheid. De gemeente doet er goed aan om voor classificatie wel het een en ander te regelen conform de onderstaande BIO2-maatregelen. Bij dataclassificatie hoort bijvoorbeeld classificatiebeleid en -procedures en labelling van informatie. Met basis beveiligingsniveau wordt bedoeld dat de uitkomst van een dataclassificatietoets ook kan leiden tot het treffen van bepaalde maatregelen die behoren bij de dataclassificatie van te voren bepaald zijn. Een voorbeeld hiervan is de ABDO of ABRO maar het kan ook een gemeentelijke set van maatregelen zijn die bij een bepaalde dataclassificatie hoort. )*
A12: Verwijzingen in de Cyberbeveiligingswet (Cbw) en Cyberbeveiligingsbesluit (Cbb): Cbw art. 21.3.i Cbb art. 16.1, 16.2, 16.3 Verwijzingen naar de Baseline Informatiebeveiliging Overheid versie 2 (BIO2): 5.12.01 - "Informatie in alle informatiesystemen is door middel van een expliciete risicoafweging geclassificeerd. Hierbij wordt gebruik gemaakt van een vastgestelde impactclassificatiemethodiek die onderdeel is van de vastgestelde risicomanagementmethodiek."
A14: Relaties met andere BIO2 producten:
A15: • Baseline Informatiebeveiliging Overheid versie 2 (BIO2) • Informatiebeveiligingsbeleid van de gemeente • Kans en schade tabellen • Handreiking risicomanagement voor gemeenten • Privacy Data Protection Impact Assessment • Diepgaande risicoanalyse methode gemeenten
A16: 1.2 Niveaus
... A20: Beschikbaarheid
A21: =_xlfn.TEXTJOIN(" - ",TRUE,"Beschikbaarheid: hoeveel en wanneer data toegankelijk is en gebruikt kan worden. De onderscheiden niveaus zijn: ",Beschikbaarheid!H4,Beschikbaarheid!G4,Beschikbaarheid!F4,Beschikbaarheid!E4,Beschikbaarheid!D4,) -> Beschikbaarheid: hoeveel en wanneer data toegankelijk is en gebruikt kan worden. De onderscheiden niveaus zijn: - Verwaarloosbaar - Gering - Gemiddeld - Kritiek/ Zeer ernstig - Catastrofaal
A22: =_xlfn.TEXTJOIN(" - ",TRUE,Beschikbaarheid!B31,Beschikbaarheid!C31) -> Verwaarloosbaar - Wanneer gegevens of systemen met deze classificatie tijdelijk uitvallen, is dat vrijwel zonder gevolgen. Een dataverlies van een week of meer of een systeemuitval die oploopt tot meer dan een week kan zonder merkbare schade worden opgevangen. Kernactiviteiten blijven doorgaan, hooguit met lichte vertraging, en de informatie kan eenvoudig worden vervangen of hersteld. Voor burgers of bestuurders is er geen voelbare impact en de continuïteit van de organisatie komt niet in gevaar.
A23: =_xlfn.TEXTJOIN(" - ",TRUE,Beschikbaarheid!B30,Beschikbaarheid!C30) -> Gering - Bij dit niveau is er sprake van enige afhankelijkheid van de informatievoorziening, maar de gevolgen van verstoringen blijven overzichtelijk. Een dataverlies van maximaal 24 uur of een systeemuitval van maximaal 1 week kan leiden tot hinder in processen, maar de dienstverlening blijft grotendeels doorgaan. Herstel vraagt wel enige inspanning en planning, maar is goed uitvoerbaar. Voor burgers is er beperkte merkbare overlast en het vertrouwen in de organisatie blijft in stand.
A24: =_xlfn.TEXTJOIN(" - ",TRUE,Beschikbaarheid!B29,Beschikbaarheid!C29) -> Gemiddeld - Wanneer de beschikbaarheid op dit niveau is geclassificeerd, zijn de gevolgen van uitval duidelijk merkbaar. Een dataverlies van 8 - 24 uur of een systeemuitval van maximaal 2 werkdagen heeft aanzienlijke invloed op kernactiviteiten en kan leiden tot klachten of verminderde dienstverlening. Het herstel van de informatie of systemen vergt aanzien redelijke inspanning en brengt extra kosten met zich mee. De maatschappelijke impact wordt zichtbaar, maar met voldoende inzet is herstel nog goed mogelijk.
A25: =_xlfn.TEXTJOIN(" - ",TRUE,Beschikbaarheid!B28,Beschikbaarheid!C28) -> Kritiek/ Zeer ernstig - Op dit niveau betekent uitval dat de continuïteit van cruciale processen ernstig in gevaar komt. Een dataverlies van 4 tot 8 uur of een systeemuitval van maximaal 8 uur kan strategische processen stilleggen. De informatie is moeilijk te vervangen en het herstel vergt veel tijd, middelen en geld. De gevolgen worden breed gevoeld, zowel in de organisatie als daarbuiten, en kunnen leiden tot forse maatschappelijke ontwrichting en bestuurlijke druk.
A26: =_xlfn.TEXTJOIN(" - ",TRUE,Beschikbaarheid!B27,Beschikbaarheid!C27) -> Catastrofaal - Deze classificatie is voor processen en gegevens waarbij geen uitval acceptabel is. Al een dataverlies van enkele uren of een systeemuitval van enkele uren kan leiden tot onherstelbare schade en bestuurlijke crisis. De informatie is onvervangbaar en de processen die ermee samenhangen zijn vitaal voor de samenleving. Continuïteit moet permanent worden gewaarborgd: near real-time beschikbaarheid is noodzakelijk. Uitval raakt direct de kern van de organisatie en kan het vertrouwen van burgers en bestuur onherstelbaar aantasten.
A27: Integriteit
A28: =_xlfn.TEXTJOIN(" - ",TRUE,_xlfn._LONGTEXT("Integriteit: het in overeenstemming zijn van informatie met de werkelijkheid en dat niets ten onrechte is achtergehouden of verdwenen (juistheid, volledigheid en tijdigheid). In deze (data)classificatiemethode worden integriteit en authenticiteit gezamenl","ijk beoordeeld, omdat verlies van authenticiteit zich in de praktijk manifesteert als foutieve of misleidende informatie en dus dezelfde impactdimensies kent. De onderscheiden niveaus zijn:"),Integriteit!H3,Integriteit!G3,Integriteit!F3,Integriteit!E3,Integriteit!D3) -> Integriteit: het in overeenstemming zijn van informatie met de werkelijkheid en dat niets ten onrechte is achtergehouden of verdwenen (juistheid, volledigheid en tijdigheid). In deze (data)classificatiemethode worden integriteit en authenticiteit gezamenlijk beoordeeld, omdat verlies van authenticiteit zich in de praktijk manifesteert als foutieve of misleidende informatie en dus dezelfde impactdimensies kent. De onderscheiden niveaus zijn: - Verwaarloosbaar - Gering - Gemiddeld - Kritiek/ Zeer ernstig - Catastrofaal
A29: =_xlfn.TEXTJOIN(" - ",TRUE,Integriteit!B26,Integriteit!C26) -> Verwaarloosbaar - Fouten of manipulaties in de informatie hebben geen merkbare gevolgen. Managementbeslissingen blijven correct, omdat de betrouwbaarheid van de gegevens niet wordt aangetast. Het risico op fraude is verwaarloosbaar en de processen blijven ongestoord functioneren. Het vertrouwen van burgers, ketenpartners en medewerkers blijft intact. Er zijn geen juridische consequenties of extra kosten te verwachten en het moreel van de medewerkers ondervindt geen enkele negatieve invloed.
A30: =_xlfn.TEXTJOIN(" - ",TRUE,Integriteit!B25,Integriteit!C25) -> Gering - Fouten of manipulaties hebben beperkte gevolgen. Beslissingen kunnen incidenteel worden beïnvloed, maar niet op een manier die de organisatie langdurig schaadt. Het risico op fraude is aanwezig, maar beperkt in omvang. Processen ondervinden hooguit kortdurende hinder en het vertrouwen van burgers of ketenpartners wordt slechts licht geraakt. Juridische of financiële gevolgen zijn minimaal en eenvoudig op te vangen. Medewerkers merken weinig en herstel is relatief eenvoudig en snel uit te voeren.
A31: =_xlfn.TEXTJOIN(" - ",TRUE,Integriteit!B24,Integriteit!C24) -> Gemiddeld - Fouten of manipulaties hebben merkbare gevolgen. Managementbeslissingen kunnen duidelijk worden beïnvloed door onjuiste informatie, wat kan leiden tot verkeerd beleid of onjuiste keuzes. Het risico op fraude is significant en kernprocessen kunnen aanzienlijke vertraging oplopen. Burgers en ketenpartners verliezen merkbaar vertrouwen in de dienstverlening. Er zijn reële juridische risico’s en de extra kosten om te herstellen zijn aanzienlijk. Medewerkers ervaren een daling in motivatie doordat fouten en herstelwerk druk veroorzaken. Herstel is mogelijk, maar kostbaar en tijdsintensief.
A32: =_xlfn.TEXTJOIN(" - ",TRUE,Integriteit!B23,Integriteit!C23) -> Kritiek/ Zeer ernstig - Fouten of manipulaties veroorzaken grote gevolgen. Beslissingen van management of bestuur worden sterk beïnvloed door verkeerde informatie, waardoor de koers van de organisatie ernstig kan ontsporen. Fraude is aannemelijk en kan omvangrijk zijn. Kernprocessen komen grotendeels stil te liggen en het vertrouwen van burgers en ketenpartners krijgt forse en blijvende schade. Juridische claims zijn waarschijnlijk en de bijkomende kosten lopen hoog op. Het moreel van medewerkers komt zwaar onder druk te staan. Herstel is zeer moeilijk en vergt langdurige inspanningen.
A33: =_xlfn.TEXTJOIN(" - ",TRUE,Integriteit!B22,Integriteit!C22) -> Catastrofaal - Fouten of manipulaties leiden tot zeer zware gevolgen. Verkeerde of misleidende informatie veroorzaakt structurele fouten in management- en beleidsbeslissingen. Grootschalige fraude wordt mogelijk en strategische processen worden langdurig onderbroken of zelfs volledig lamgelegd. Het vertrouwen van burgers, partners en medewerkers gaat blijvend verloren. De organisatie wordt geconfronteerd met zware juridische aansprakelijkheid en extreme herstelkosten. Het moreel van medewerkers wordt ernstig geschaad, waardoor motivatie en loyaliteit verdwijnen. Herstel is nauwelijks nog mogelijk en de schade is grotendeels onomkeerbaar.
A34: Vertrouwelijkheid
A35: =_xlfn.TEXTJOIN(" - ",TRUE,"Vertrouwelijkheid: de bevoegdheden en de mogelijkheden tot muteren, kopiëren, toevoegen, vernietigen of kennisnemen van informatie voor een gedefinieerde groep van gerechtigden. De onderscheiden niveaus zijn: ",Vertrouwelijkheid!H3,Vertrouwelijkheid!G3,Vertrouwelijkheid!F3,Vertrouwelijkheid!E3,Vertrouwelijkheid!D3) -> Vertrouwelijkheid: de bevoegdheden en de mogelijkheden tot muteren, kopiëren, toevoegen, vernietigen of kennisnemen van informatie voor een gedefinieerde groep van gerechtigden. De onderscheiden niveaus zijn: - Openbaar - Intern - Vertrouwelijk - Confidentieel - Geheim / Zeer Geheim
A36: =_xlfn.TEXTJOIN(" - ",TRUE,Vertrouwelijkheid!B29,Vertrouwelijkheid!C29) -> Openbaar - Het gaat hier om informatie die zonder risico gedeeld kan worden met iedereen. De gegevens zijn ongerubriceerd (hoeven niet als zodanig gemarkeerd te worden) en bedoeld voor openbaarheid, bijvoorbeeld op de gemeentelijke website of in een folder. Ongeautoriseerde kennisname is toegestaan en levert geen schade op. Er is dus geen noodzaak om deze informatie extra af te schermen of te beveiligen. Het gaat hierbij om openbare gegevens. De gegevens hoeven niet afgeschermd te worden. Let wel op, deze gegevens kunnen nog steeds integer, authentiek en beschikbaar moeten zijn.
A37: =_xlfn.TEXTJOIN(" - ",TRUE,Vertrouwelijkheid!B28,Vertrouwelijkheid!C28) -> Intern - Dit betreft informatie die binnen de organisatie moet blijven, maar waarvan de gevolgen van openbaarmaking nog beperkt zijn. Onbevoegde kennisname is ongewenst, omdat dit hinder kan veroorzaken of herstelwerk nodig maakt. De vertrouwelijkheid is hier vooral een praktische randvoorwaarde: er kan sprake zijn van lichte reputatieschade of interne verstoring, maar de gevolgen zijn doorgaans herstelbaar.
A38: =_xlfn.TEXTJOIN(" - ",TRUE,Vertrouwelijkheid!B27,Vertrouwelijkheid!C27) -> Vertrouwelijk - Bij dit niveau gaat het om informatie die gevoeliger is en waarbij de overheid weerstand tegen spionage en misbruik moet organiseren. Ongeautoriseerde openbaarmaking is schadelijk en moet zoveel mogelijk worden voorkomen. De gevolgen kunnen aanzienlijk zijn: reputatieschade, juridische claims en verstoring van de samenwerking met partners. Bij dit niveau wordt minimaal BIO2 toegepast, aangevuld met risicomanagement en waar nodig extra maatregelen tegen statelijke actoren, zoals monitoring, logging of leveranciersscreening. Dit is ook het niveau waarop de Dep.V-maatregelen uit Algemene Beveiligingseisen voor Defensieopdrachten (ABDO) of Algemene Beveiligingseisen voor Rijksoverheidsopdrachten (ABRO) relevant worden.
A39: =_xlfn.TEXTJOIN(" - ",TRUE,Vertrouwelijkheid!B26,Vertrouwelijkheid!C26) -> Confidentieel - Dit betreft informatie die van zo’n grote gevoeligheid is dat openbaarmaking ernstig schadelijk zou zijn. Ongeautoriseerde kennisname moet actief en strikt worden voorkomen. De gevolgen zijn groot: blijvende schade aan vertrouwen in de overheid, aanzienlijke juridische claims en hoge herstelkosten. Op dit niveau gelden altijd aanvullende beveiligingsregels uit Algemene Beveiligingseisen voor Defensieopdrachten (ABDO) of Algemene Beveiligingseisen voor Rijksoverheidsopdrachten (ABRO). BIO2 alleen is niet voldoende, omdat hier nationale veiligheid en staatsbelangen in het geding zijn.
A40: =_xlfn.TEXTJOIN(" - ",TRUE,Vertrouwelijkheid!B25,Vertrouwelijkheid!C25) -> Geheim / Zeer Geheim - Dit is de hoogste vertrouwelijkheidsklasse en geldt voor informatie waarvan openbaarmaking catastrofale gevolgen heeft voor de samenleving of de nationale veiligheid. Ongeautoriseerde kennisname is volledig onacceptabel. Het verlies van deze informatie zou vitale belangen direct in gevaar brengen en kan leiden tot ernstige maatschappelijke ontwrichting of crisis. Beveiliging op dit niveau is zeer zwaar en strikt gereguleerd volgens Algemene Beveiligingseisen voor Defensieopdrachten (ABDO) of Algemene Beveiligingseisen voor Rijksoverheidsopdrachten (ABRO), vaak in combinatie met intensief toezicht door bevoegde veiligheidsdiensten. Risicomanagement kan aanvullend worden toegepast, maar de primaire leidraad is dat geen enkel risico acceptabel is. Dit niveau komt bij gemeenten zeer waarschijnlijk niet voor.
A42: Uitgevoerde BIO2 classificatietoetsen, risicoanalyses en/of DPIA’s maken onderdeel uit van het systeemdossier en moeten worden bewaard zo lang als het informatiesysteem in gebruik is. Dit is nodig omdat zowel de Cbw als de Algemene Verordening Gegevensbescherming (AVG) praten over "passende maatregelen" dat moet dus ook achteraf aantoonbaar zijn.
A43: 1.3 Belang informatie
A45: Het bepalen van het belang van de informatie gebeurt door na te gaan hoe groot de impact is die kan ontstaan als het betreffende betrouwbaarheidsaspect (beschikbaarheid, integriteit of vertrouwelijkheid) van de informatie niet in orde is en leidt tot impact op het proces. Het toekennen van waarden (per betrouwbaarheidsaspect) is specifiek voor de dienst en/of het betreffende verantwoordelijkheidsgebied.
A46: Invalshoeken om tot een waardebepaling te komen zijn bijvoorbeeld:
A47: • Persoonlijke veiligheid
A48: Bijvoorbeeld: Wordt de veiligheid van personen bedreigd als gegevens niet beschikbaar zijn, een systeem uitvalt, of als er verkeerde informatie wordt verstrekt? Zo ja, hoe ernstig zijn de gevolgen?
A49: • Persoonsgegevens
...

Sheet Algemene Vragen
A1: Algemene vragen over de informatie
A3: 0. | B3: Algemeen | D3: Let op, alleen de gele velden invullen!
B4: Organisatie:
B5: <organisatienaam>
B7: Afdeling:
B8: <afdeling/ bureau/ et cetera>
B10: Opsteller:
B11: <opsteller baselinetoets>
B13: Versienummer:
B14: <versienummer>
B16: Datum:
B17: <datum uitvoering informatie classificatie>
A20: 1. | B20: Management samenvatting
A23: 2. | B23: Inleiding
B24: <In te vullen door de invuller, waarom wordt deze informatie classificatie BIO uitgevoerd, door wie, wie is benaderd et cetera.>
A27: 2.1 | B27: Project
B28: <Korte samenvatting van het project; verwijzen naar een Programma Start Architectuur (PSA) en/ of projectvoorstel, niet langer dan 1A4.>
A31: 3. | B31: Vragenlijst informatie
A33: 3.1. | B33: Naam en functie geïnterviewde
B34: <Interview met bedrijfsproces (business), informatie eigenaar en bij een groepssessie, meerdere namen benoemen en hun rol.>
A37: 3.2 | B37: Naam en functie proces waar de informatie gebruikt wordt
B38: <Om welk proces gaat het, wat is het doel?>
A41: 3.3 | B41: Geef een bondige beschrijving van het proces/ processen en de informatie en benoem de proces (informatie) eigenaar.
B42: <Alle hoofdprocessen benoemen> <Let op: bij meerdere proceseigenaren, alle betrokken proceseigenaren interviewen> <Let op: Geef ook aan of het proces of de subprocessen 24/7 dienstverlening betreft of dat er in bepaalde perioden hoge beschikbaarheid nodig is (jaar, maand et cetera)>
A45: 3.4 | B45: Maakt het proces/ de processen deel uit van een keten/ meerdere ketens, of zijn anderen afhankelijk van de informatie? Zo ja beschrijf de keten/ ketens
B46: Wat is (zijn) de keten(s): Wat is (zijn) de ketenpartner(s):
A49: 3.5 | B49: Welke eventuele subprocessen zijn te onderscheiden? Welke hoofdactiviteiten worden binnen het proces uitgevoerd en wie doen dat?
A53: 3.6 | B53: Welke informatie wordt er gebruikt binnen het proces en eventuele subprocessen? Geef ook aan welke soort persoonsgegevens gebruikt worden. Deze gegevens zijn het onderwerp van de dataclassificatie.
B54: <Vermeld hier welke gegevens worden verzameld/verwerkt binnen het proces, probeer zo volledig mogelijk te zijn.> Gegevens: • <Bijvoorbeeld financiële gegevens.> Persoonsgegevens: • <Bijvoorbeeld naam, adres en woonplaats, telefoonnummers of postcodes met huisnummers.> Bijzondere persoonsgegevens: • <Bijvoorbeeld burgerservicenummer (BSN), godsdienst of levensovertuiging, ras, politieke gezindheid, medische gegevens, seksuele leven, lidmaatschap van een vakvereniging, strafrechtelijke/ justitiële persoonsgegevens.>
A58: 3.7 | B58: Beschrijf welke informatie afnemers het proces heeft. Welke informatie nemen zij af en welke kwaliteitseisen stellen zij aan deze informatie?
A63: 3.8 | B63: Beschrijf welke informatie leveranciers het proces heeft. Welke informatie leveren zij aan en welke eisen stellen zij aan de informatie die in het proces gebruikt wordt?
A68: 3.9 | B68: Welke wet- en regelgeving is van toepassing op deze informatie proces en welke specifieke eisen komen hieruit naar voren?
B69: Op dit informatiesysteem is de onderstaande wet- en regelgeving op het gebied van Informatiebeveiliging en Privacy van toepassing : <Algemene Verordening Gegevensbescherming (AVG) Wet Basisregistratie Personen (BRP) Archiefwet SUWI-net et cetera (aanvullen)>
A72: 3.10 | B72: Door welke informatievoorziening/ systemen wordt de informatie verwerkt?
A76: 3.11 | B76: (beoogd) Eigenaar van de informatie
B77: <Let op: eigenaar moet in deze fase bekend zijn, of benoemd worden.>

Sheet Beschikbaarheid
B1: Blok beschikbaarheidsvragen voor dataclassificatie van informatie | K1: Extra uitleg, wordt niet geprint
B2: Gevolgen van het niet beschikbaar hebben van de benodigde informatie of gegevens. | E2: Waardering | I2: Argumentatie | K2: Let op, alleen de gele velden invullen!
B3: (in het ergste geval) | E3: (zie de waardering bij de vraag) | I3: (verplicht invullen)
D4: Catastrofaal | E4: Kritiek/ Zeer ernstig | F4: Gemiddeld | G4: Gering | H4: Verwaarloosbaar
B5: B1 | C5: Managementbeslissingen | D5: Uren | E5: Dag (deel) | F5: Week | G5: Meer dan een week | H5: Meer dan 2 weken | I5: Kies per vraag / rij één antwoord van 0 of 1 zie waarderingstabel onderaan met de omschrijvingen.
C6: Welke tijdsduur, die het nemen van beslissingen door het ontbreken van informatie, negatief beïnvloedt, is acceptabel.? | D6: 0 | E6: 0 | F6: 0 | G6: 0 | H6: 0
B7: B2 | C7: Imagoverlies | D7: Uren | E7: Dag (deel) | F7: Week | G7: Meer dan een week | H7: Meer dan 2 weken
C8: Hoe lang duurt het voordat er sprake is van imagoverlies wanneer informatie niet voorhanden is? | D8: 0 | E8: 0 | F8: 0 | G8: 0 | H8: 0 | K8: Imagoverlies is lastig omdat je als organisatie soms lang tijd hebt voor bepaalde beslissingen. Bedenk ook dat er soms een maximum (wettelijke) termijn is dat sommige informatie niet beschikbaar mag zijn.
B9: B3 | C9: Hapering dienstverlening | D9: Hersteltijd max 4 werkuren | E9: Hersteltijd max 8 werkuren | F9: Hersteltijd max 16 werkuren | G9: Hersteltijd max 40 werkuren | H9: Hersteltijd meer dan 40 werkuren | I9: <Dataverlies (Recovery-Point Objective (RPO)) en hersteltijd (Recovery-Time Objective (RTO)) zijn doelstellingen die een belangrijke rol spelen bij disaster recovery. | K9: Let wel op, in de hersteltijd zit ook het herstellen van gegevens zodat het proces weer normaal kan plaatsvinden.
C10: Hoe lang kan de informatie niet beschikbaar zijn voordat er daadwerkelijk hapering in de dienstverlening aan burgers/bedrijven/ketenpartners ontstaat? Hoe snel moet er worden hersteld? | D10: 0 | E10: 0 | F10: 0 | G10: 0 | H10: 0 | I10: Binnen welke tijdsperiode (RTO) moet de dienstverlening weer hersteld zijn?
I11: Deze vraag heeft betrekking op de hersteltijd (RTO).
I12: Vraag B7 heeft betrekking op het dataverlies (RPO).>
B13: B4 | C13: Wettelijke aansprakelijkheid | D13: Dag (deel) | E13: Dag (deel) | F13: Week | G13: Meer dan een week | H13: Meer dan 2 weken | K13: Let wel op, je kunt situaties hebben dat de beschikbaarheid / uitval een week mag zijn, behalve op de dag dat de uitkeringen worden berekend en naar de bank gezonden. Geef dat dan aan in de rapportage en bedenk daar later mitigerende maatregelen voor.
C14: Hoe lang kan de informatie niet beschikbaar zijn voordat er wettelijke of contractuele verplichtingen niet kunnen worden nagekomen? | D14: 0 | E14: 0 | F14: 0 | G14: 0 | H14: 0
B15: B5 | C15: Additionele kosten | D15: Dag (deel) | E15: Dag (deel) | F15: Week | G15: Meer dan een week | H15: Meer dan 2 weken | K15: Bijvoorbeeld: het betalen van uitkeringen mag geen dag te laat zijn. Als dat echt niet mag gebeuren doe daar geen RA voor maar noteer het wel hier en bedenk een proces om daarmee om te gaan.
C16: Na welke periode zijn additionele kosten voor de organisatie te verwachten, bij het niet beschikbaar zijn van de informatie? | D16: 0 | E16: 0 | F16: 0 | G16: 0 | H16: 0
B17: B6 | C17: Moreel van de medewerkers | D17: Uren | E17: Dag (deel) | F17: Week | G17: Meer dan een week | H17: Meer dan 2 weken | K17: Bedenk hier ook dat er een wettelijke plicht is om bepaalde systemen tijdig in de lucht te hebben. Bijvoorbeeld Suwi, BRP en PUN.
C18: Na welke periode is er sprake van een duidelijk negatieve invloed op het moreel en de motivatie van medewerkers, wanneer de informatie stroom hapert? | D18: 0 | E18: 0 | F18: 0 | G18: 0 | H18: 0
B19: B7 | C19: Herstel: | D19: Dataverlies minder dan 4 uur | E19: Dataverlies tot 8 uur | F19: Dataverlies: 8-24 uur | G19: Dataverlies meer dan 24 uur | H19: Dataverlies meer dan een week | I19: <Dataverlies (Recovery-Point Objective (RPO)) en hersteltijd (Recovery-Time Objective (RTO)) zijn doelstellingen die een belangrijke rol spelen bij disaster recovery.
C20: Hoe lang mag het herstellen na een onbeschikbaarheid de informatie duren voordat er daadwerkelijk hapering in de dienstverlening aan burgers/ bedrijven/ ketenpartners ontstaat? Zijn er hoge herstelkosten? Dus achteraf verwerken van verloren gegaan werk. | D20: 0 | E20: 0 | F20: 0 | G20: 0 | H20: 0 | I20: Hoeveel dataverlies (RPO) is acceptabel en binnen welke tijdsperiode moet dit hersteld kunnen worden.
I21: Deze vraag heeft betrekking op het dataverlies (RPO).>
I22: Vraag B3 heeft betrekking op de hersteltijd (RTO).
B23: Wat is de meest serieuze impact als de informatie onbeschikbaar is? | D23: =MAX(D6:D22) -> 0 | E23: =MAX(E6:E22) -> 0 | F23: =MAX(F6:F22) -> 0 | G23: =MAX(G5:G21) -> 0 | H23: =MAX(H5:H21) -> 0 | I23: =IF(OR(SUM(E6:H22)<7,SUM(E6:H22)>7),"Er zijn te veel of te weinig antwoorden gegeven, vul per vraag maar 1 waarde in!"," ") -> Er zijn te veel of te weinig antwoorden gegeven, vul per vraag maar 1 waarde in!
B24: Beschikbaarheid Resultaat | D24: =IF(D23>0,D4, " ") | E24: =IF(E23>0,E4, " ") | F24: =IF(F23>0,F4, " ") | G24: =IF(G23>0,G4, " ") | H24: =IF(H23>0,H4, " ")
B25: Wat is de beschikbaarheidsclassificatie van de informatie | D25: =IF(D24=D4,D4,IF(E24=E4, E4,IF(F24="Noodzakelijk",F24,IF(G24="Belangrijk",G24,IF(H24="Niet Zeker",H24,"Niets ingevuld"))))) -> Niets ingevuld | I25: =IF(D24=D4,"De BIO2 moet worden gevolgd om tot extra beschikbaarheids maatregelen te komen tevens een RA uitvoeren.",IF(E24=E4,"De BIO2 moet worden gevolgd om tot extra beschikbaarheids maatregelen te komen tevens een RA uitvoeren.",IF(F24=F4,"De te kiezen beschikbaarheidsmaatregelen uit de BIO2 kunnen voldoede zijn, voer eventueel een RA uit.",IF(G24=G4,"De beschikbaarheidsmaaatregelen uit de BIO2 zijn voldoende",IF(H24=H4,"Er is een minimale beschikbaarheidseis vastgesteld, er kunnen nog steeds enkele maatregelen gekozen worden om de uitval niet meer dan 2 weken te laten zijn.","De beschikbaarheidsclassificatie is nog niet vastgesteld."))))) -> De beschikbaarheidsclassificatie is nog niet vastgesteld.
B26: Impact | C26: Omschrijving beschikbaarheid
B27: =D4 -> Catastrofaal | C27: Deze classificatie is voor processen en gegevens waarbij geen uitval acceptabel is. Al een dataverlies van enkele uren of een systeemuitval van enkele uren kan leiden tot onherstelbare schade en bestuurlijke crisis. De informatie is onvervangbaar en de processen die ermee samenhangen zijn vitaal voor de samenleving. Continuïteit moet permanent worden gewaarborgd: near real-time beschikbaarheid is noodzakelijk. Uitval raakt direct de kern van de organisatie en kan het vertrouwen van burgers en bestuur onherstelbaar aantasten.
B28: =E4 -> Kritiek/ Zeer ernstig | C28: Op dit niveau betekent uitval dat de continuïteit van cruciale processen ernstig in gevaar komt. Een dataverlies van 4 tot 8 uur of een systeemuitval van maximaal 8 uur kan strategische processen stilleggen. De informatie is moeilijk te vervangen en het herstel vergt veel tijd, middelen en geld. De gevolgen worden breed gevoeld, zowel in de organisatie als daarbuiten, en kunnen leiden tot forse maatschappelijke ontwrichting en bestuurlijke druk.
B29: =F4 -> Gemiddeld | C29: Wanneer de beschikbaarheid op dit niveau is geclassificeerd, zijn de gevolgen van uitval duidelijk merkbaar. Een dataverlies van 8 - 24 uur of een systeemuitval van maximaal 2 werkdagen heeft aanzienlijke invloed op kernactiviteiten en kan leiden tot klachten of verminderde dienstverlening. Het herstel van de informatie of systemen vergt aanzien redelijke inspanning en brengt extra kosten met zich mee. De maatschappelijke impact wordt zichtbaar, maar met voldoende inzet is herstel nog goed mogelijk.
B30: =G4 -> Gering | C30: Bij dit niveau is er sprake van enige afhankelijkheid van de informatievoorziening, maar de gevolgen van verstoringen blijven overzichtelijk. Een dataverlies van maximaal 24 uur of een systeemuitval van maximaal 1 week kan leiden tot hinder in processen, maar de dienstverlening blijft grotendeels doorgaan. Herstel vraagt wel enige inspanning en planning, maar is goed uitvoerbaar. Voor burgers is er beperkte merkbare overlast en het vertrouwen in de organisatie blijft in stand.
B31: =H4 -> Verwaarloosbaar | C31: Wanneer gegevens of systemen met deze classificatie tijdelijk uitvallen, is dat vrijwel zonder gevolgen. Een dataverlies van een week of meer of een systeemuitval die oploopt tot meer dan een week kan zonder merkbare schade worden opgevangen. Kernactiviteiten blijven doorgaan, hooguit met lichte vertraging, en de informatie kan eenvoudig worden vervangen of hersteld. Voor burgers of bestuurders is er geen voelbare impact en de continuïteit van de organisatie komt niet in gevaar.

Sheet Integriteit
B1: Blok integriteitsvragen voor dataclassificatie van informatie | K1: Extra uitleg, wordt niet geprint
B2: Gevolgen van fouten in informatie of doelbewuste manipulatie van informatie om te frauderen of fraude te maskeren | E2: Waardering | I2: Argumentatie | K2: Let op, alleen de gele velden invullen!
B3: (in het ergste geval) | D3: Catastrofaal | E3: Kritiek/ Zeer ernstig | F3: Gemiddeld | G3: Gering | H3: Verwaarloosbaar | I3: (verplicht invullen)
B4: I1 | C4: Managementbeslissingen | D4: Zeer zware gevolgen | E4: Zware gevolgen | F4: Gemiddelde gevolgen | G4: Beperkte gevolgen | H4: Verwaarloosbaar/ Geen gevolgen
C5: Kan onjuiste informatie leiden tot onjuiste beslissingen? Wat zijn de gevolgen? | D5: 0 | E5: 0 | F5: 0 | G5: 0 | H5: 0
B6: I2 | C6: Fraude potentie | D6: Zeer zware schade | E6: Zware schade | F6: Gemiddelde schade | G6: Beperkte schade | H6: Verwaarloosbaar/ Geen schade
C7: Zijn er frauderisico’s met deze informatie, en welke gevolgen hebben deze? | D7: 0 | E7: 0 | F7: 0 | G7: 0 | H7: 0
B8: I3 | C8: Onderbreking van strategische processen | D8: Zeer hoog | E8: Hoog | F8: Gemiddeld | G8: Beperkt | H8: Verwaarloosbaar
C9: In hoeverre kunnen de kernprocessen van de organisatie onderbroken worden als gevolg van ongeautoriseerde wijzigingen van, of fouten in informatie? | D9: 0 | E9: 0 | F9: 0 | G9: 0 | H9: 0
B10: I4 | C10: Vertrouwen van het publiek c.q. klanten | D10: Zeer zwaar | E10: Zwaar | F10: Gemiddeld | G10: Beperkt | H10: Verwaarloosbaar
C11: Kan het vertrouwen van het publiek geschaad worden door onjuiste informatie? | D11: 0 | E11: 0 | F11: 0 | G11: 0 | H11: 0
B12: I5 | C12: Wettelijke aansprakelijkheid | D12: Zeer zwaar | E12: Zwaar | F12: Gemiddeld | G12: Beperkt | H12: Verwaarloosbaar
C13: Wat kunnen de gevolgen zijn van het niet voldoen aan wettelijke of contractuele verplichtingen die veroorzaakt worden door onjuiste informatie? | D13: 0 | E13: 0 | F13: 0 | G13: 0 | H13: 0
B14: I6 | C14: Additionele kosten | D14: Zeer hoge kosten | E14: Hoge kosten | F14: Gemiddelde kosten | G14: Lage kosten | H14: Verwaarloosbaar
C15: In hoeverre kunnen er additionele kosten ontstaan door het toepassen van onjuiste informatie? Bijvoorbeeld door het moeten herstellen van een corrupte database of opnieuw invoeren van gegevens. | D15: 0 | E15: 0 | F15: 0 | G15: 0 | H15: 0
B16: I7 | C16: Moreel van de medewerkers | D16: Zeer zwaar | E16: Zwaar | F16: Gemiddeld | G16: Beperkt | H16: Verwaarloosbaar
C17: Wat zijn de schadelijke effecten op het moreel van medewerkers als u onjuiste informatie gebruikt? | D17: 0 | E17: 0 | F17: 0 | G17: 0 | H17: 0
C18: Maximale Waarde | D18: =MAX(D4:D17) -> 0 | E18: =MAX(E4:E17) -> 0 | F18: =MAX(F4:F17) -> 0 | G18: =MAX(G4:G17) -> 0 | H18: =MAX(H4:H17) -> 0 | I18: =IF(OR(SUM(E3:G17)<7,SUM(E3:G17)>7),"Er zijn te veel of te weinig antwoorden gegeven, vul per vraag maar 1 waarde in!"," ") -> Er zijn te veel of te weinig antwoorden gegeven, vul per vraag maar 1 waarde in!
B19: Classificatie resultaat | D19: =IF(D18>0,D3, " ") | E19: =IF(E18>0,E3, " ") | F19: =IF(F18>0,F3, " ") | G19: =IF(G18>0,G3, " ") | H19: =IF(H18>0,H3, " ")
B20: Wat is de classificatie van de integriteit van de informatie, passend bij de kans en impact tabel? | D20: =IF(D19=D3,D3,IF(E19=E3,E3,IF(F19=F3,F3,IF(G19=G3,G3,IF(H19=H3,H3,"Niets ingevuld"))))) -> Niets ingevuld | I20: =IF(D19=D3,"De BIO2 en aanvullende risicoanalyse moet worden gebruikt om extra integriteitsmaatregelen te bepalen",IF(E19=E3,"De BIO2 en aanvullende risicoanalyse moet worden gebruikt om extra integriteitsmaatregelen te bepalen",IF(F19=F3,"De BIO2 basismaatregelen gemeenten kunnen worden gebruikt",IF(G19=G3,"Alleen de overheidsmaatregeln uit de BIO2 kunnen voldoende zijn",IF(H19=H3,"De vastgestelde Ingeriteitsclassificatie is zeer laag', er kunnen nog steeds enkele maatregelen gekozen worden om de integriteit te waarborgen","De integriteitsclassificatie is nog niet vastgesteld."))))) -> De integriteitsclassificatie is nog niet vastgesteld.
B21: Impact | C21: Omschrijving integriteit
B22: =D3 -> Catastrofaal | C22: Fouten of manipulaties leiden tot zeer zware gevolgen. Verkeerde of misleidende informatie veroorzaakt structurele fouten in management- en beleidsbeslissingen. Grootschalige fraude wordt mogelijk en strategische processen worden langdurig onderbroken of zelfs volledig lamgelegd. Het vertrouwen van burgers, partners en medewerkers gaat blijvend verloren. De organisatie wordt geconfronteerd met zware juridische aansprakelijkheid en extreme herstelkosten. Het moreel van medewerkers wordt ernstig geschaad, waardoor motivatie en loyaliteit verdwijnen. Herstel is nauwelijks nog mogelijk en de schade is grotendeels onomkeerbaar.
B23: =E3 -> Kritiek/ Zeer ernstig | C23: Fouten of manipulaties veroorzaken grote gevolgen. Beslissingen van management of bestuur worden sterk beïnvloed door verkeerde informatie, waardoor de koers van de organisatie ernstig kan ontsporen. Fraude is aannemelijk en kan omvangrijk zijn. Kernprocessen komen grotendeels stil te liggen en het vertrouwen van burgers en ketenpartners krijgt forse en blijvende schade. Juridische claims zijn waarschijnlijk en de bijkomende kosten lopen hoog op. Het moreel van medewerkers komt zwaar onder druk te staan. Herstel is zeer moeilijk en vergt langdurige inspanningen.
B24: =F3 -> Gemiddeld | C24: Fouten of manipulaties hebben merkbare gevolgen. Managementbeslissingen kunnen duidelijk worden beïnvloed door onjuiste informatie, wat kan leiden tot verkeerd beleid of onjuiste keuzes. Het risico op fraude is significant en kernprocessen kunnen aanzienlijke vertraging oplopen. Burgers en ketenpartners verliezen merkbaar vertrouwen in de dienstverlening. Er zijn reële juridische risico’s en de extra kosten om te herstellen zijn aanzienlijk. Medewerkers ervaren een daling in motivatie doordat fouten en herstelwerk druk veroorzaken. Herstel is mogelijk, maar kostbaar en tijdsintensief.
B25: =G3 -> Gering | C25: Fouten of manipulaties hebben beperkte gevolgen. Beslissingen kunnen incidenteel worden beïnvloed, maar niet op een manier die de organisatie langdurig schaadt. Het risico op fraude is aanwezig, maar beperkt in omvang. Processen ondervinden hooguit kortdurende hinder en het vertrouwen van burgers of ketenpartners wordt slechts licht geraakt. Juridische of financiële gevolgen zijn minimaal en eenvoudig op te vangen. Medewerkers merken weinig en herstel is relatief eenvoudig en snel uit te voeren.
B26: =H3 -> Verwaarloosbaar | C26: Fouten of manipulaties in de informatie hebben geen merkbare gevolgen. Managementbeslissingen blijven correct, omdat de betrouwbaarheid van de gegevens niet wordt aangetast. Het risico op fraude is verwaarloosbaar en de processen blijven ongestoord functioneren. Het vertrouwen van burgers, ketenpartners en medewerkers blijft intact. Er zijn geen juridische consequenties of extra kosten te verwachten en het moreel van de medewerkers ondervindt geen enkele negatieve invloed.
B28: Opmerking: | C28: In deze (data)classificatiemethode worden integriteit en authenticiteit gezamenlijk beoordeeld, omdat verlies van authenticiteit zich in de praktijk manifesteert als foutieve of misleidende informatie en dus dezelfde impactdimensies kent.

Sheet Vertrouwelijkheid
B1: Blok vertrouwelijkheidsvragen voor dataclassificatie van informatie | K1: Extra uitleg, wordt niet geprint
B2: Gevolgen van onbedoelde of ongeautoriseerde verspreiding van gegevens of informatie | E2: Waardering | I2: Argumentatie | K2: Let op, alleen de gele velden invullen!
B3: (in het ergste geval) | D3: Geheim / Zeer Geheim | E3: Confidentieel | F3: Vertrouwelijk | G3: Intern | H3: Openbaar | I3: (verplicht invullen)
B4: V1 | C4: Vertrouwen van de burger | D4: catastrofale gevolgen | E4: Zeer ernstige gevolgen | F4: Ernstige gevolgen | G4: Acceptabel | H4: Geen gevolgen
C5: Wat zijn de gevolgen voor de organisatie indien de binnen het proces beschikbare informatie te vroeg c.q. niet volgens de regels verspreid wordt? | D5: 0 | E5: 0 | F5: 0 | G5: 0 | H5: 0 | K5: Het vertrouwen van de burger in de organisatie wordt geschaad als informatie wordt gelekt (onbedoeld en bedoeld), maar hoe erg is dat en wat zijn de (politieke) gevolgen?
B6: V2 | C6: Vertrouwen van het publiek | D6: Catastrofale gevolgen | E6: Zeer ernstige gevolgen | F6: Ernstige gevolgen | G6: Acceptabel | H6: Geen gevolgen | I6: < Neem bij de beantwoording van deze vraag zowel persoonsgegevens als niet persoonsgegevens mee>
C7: Wat zijn de gevolgen voor het publieke imago van de organisatie als vertrouwelijke informatie van de organisatie onterecht wordt verspreid? | D7: 0 | E7: 0 | F7: 0 | G7: 0 | H7: 0 | K7: Hoe is het publieke imago van de organisatie en wat zijn de gevolgen hiervoor als informatie onterecht wordt verspreid?
B8: V3 | C8: Vertrouwen van ketenpartners | D8: Ja | E8: Ja | F8: Mogelijk | G8: Nee | H8: N.v.t.
C9: Kan de organisatie toegang tot de keten geweigerd worden? | D9: 0 | E9: 0 | F9: 0 | G9: 0 | H9: 0
B10: V4 | C10: Vertrouwen van ketenpartners | D10: Catastrofale gevolgen | E10: Zeer ernstige gevolgen | F10: Ernstige gevolgen | G10: Acceptabel | H10: Geen gevolgen
C11: Wat zijn de gevolgen voor de relatie met de ketenpartners, als vertrouwelijke informatie onterecht wordt verspreid.? | D11: 0 | E11: 0 | F11: 0 | G11: 0 | H11: 0 | K11: Wat zijn de gevolgen voor connecties met ketenpartners, Suwi, BRP?
B12: V5 | C12: (Wettelijke) Aansprakelijkheid | D12: Catastrofale gevolgen | E12: Zeer ernstige gevolgen | F12: Ernstige gevolgen | G12: Acceptabel | H12: Geen gevolgen | I12: < Neem bij de beantwoording van deze vraag zowel persoonsgegevens als niet persoonsgegevens mee>
C13: Wat zijn de gevolgen voor (wettelijke) aansprakelijkheid bij het onterecht verspreiden van deze informatie? | D13: 0 | E13: 0 | F13: 0 | G13: 0 | H13: 0 | K13: Is de organisatie aansprakelijk voor het onterecht verspreiden van informatie / persoonsgegevens en wat zijn de gevolgen daarvan?
B14: V6 | C14: Additionele kosten | D14: Zeer hoge kosten | E14: Hoge kosten | F14: Gemiddelde kosten | G14: Lage kosten | H14: Geen kosten | I14: < Neem bij de beantwoording van deze vraag zowel persoonsgegevens als niet persoonsgegevens mee. Het gaat hier dus ook over de bestuurlijke boete van de Autoriteit Persoonsgegevens en andere toezichthouders voor de Cbw> | K14: Let op: ook onterechte openbaarmaking en lekken van informatie kan een Cbw boete tot gevolg hebben.
C15: In hoeverre is er sprake van additionele kosten door onterechte verspreiding van deze informatie? | D15: 0 | E15: 0 | F15: 0 | G15: 0 | H15: 0 | K15: Denk aan herstelkosten, juridische kosten, schadevergoedingen et cetera.
B18: V7 | C18: Moreel van de medewerkers | D18: Zeer hoge invloed | E18: Hoge invloed | F18: Gemiddelde invloed | G18: Lage invloed | H18: Geen invloed | I18: < Neem bij de beantwoording van deze vraag zowel persoonsgegevens als niet persoonsgegevens mee>
C19: In hoeverre kan een duidelijk negatieve invloed op het moreel en de motivatie van medewerkers een gevolg zijn van de onterechte verspreiding van deze informatie? | D19: 0 | E19: 0 | F19: 0 | G19: 0 | H19: 0
C20: Maximale Waarde | D20: =MAX(D5:D19) -> 0 | E20: =MAX(E5:E19) -> 0 | F20: =MAX(F5:F19) -> 0 | G20: =MAX(G5:G19) -> 0 | H20: =MAX(H5:H19) -> 0 | I20: =IF(OR(SUM(E5:H19)<7,SUM(E5:H19)>7),"er zijn te veel of te weinig antwoorden gegeven, vul per vraag maar 1 waarde in!"," ") -> er zijn te veel of te weinig antwoorden gegeven, vul per vraag maar 1 waarde in!
B21: Niveau | D21: =IF(D20>0,D3, " ") | E21: =IF(E20>0,E3, " ") | F21: =IF(F20>0,F3, " ") | G21: =IF(G20>0,G3, " ") | H21: =IF(H20>0,H3, " ") | I21: =IF(D21=D3,"De BIO2 maatregelen met ABRO/ ABDO maatregelen en een aanvullende RA uitvoeren",IF(E21=E3,"De BIO2 maatregelen met ABRO/ ABDO Beschikbaarheid!1:1048576en eventueel een aanvullende RA uitvoeren",IF(F21=F3,"De classificatie is Vertrouwelijk, de BIO2 wordt gevolgt eventueel aangevuld met ABDO/ ABRO",IF(G21=G3,"De classificatie is Intern, de te kiezen beveiligingsmaatregelen uit de BIO2",IF(H21=H3,"De dataclassificatie is Openbaar, er zijn geen vertrouwelijkheidsmaatregelen uit de BIO noodzakelijk.","De vertrouwelijkheidsclassificatie is nog niet vastgesteld."))))) -> De vertrouwelijkheidsclassificatie is nog niet vastgesteld.
B22: Totaal Vertrouwelijkheid: | D22: =IF(D21=D3,D21,IF(E21=E3,E21,IF(F21=F3,F3,IF(G21=G3,G3,IF(H21=H3,H3,"Niets ingevuld"))))) -> Niets ingevuld
B24: Impact | C24: Omschrijving
B25: =D3 -> Geheim / Zeer Geheim | C25: Dit is de hoogste vertrouwelijkheidsklasse en geldt voor informatie waarvan openbaarmaking catastrofale gevolgen heeft voor de samenleving of de nationale veiligheid. Ongeautoriseerde kennisname is volledig onacceptabel. Het verlies van deze informatie zou vitale belangen direct in gevaar brengen en kan leiden tot ernstige maatschappelijke ontwrichting of crisis. Beveiliging op dit niveau is zeer zwaar en strikt gereguleerd volgens Algemene Beveiligingseisen voor Defensieopdrachten (ABDO) of Algemene Beveiligingseisen voor Rijksoverheidsopdrachten (ABRO), vaak in combinatie met intensief toezicht door bevoegde veiligheidsdiensten. Risicomanagement kan aanvullend worden toegepast, maar de primaire leidraad is dat geen enkel risico acceptabel is. Dit niveau komt bij gemeenten zeer waarschijnlijk niet voor.
B26: =E3 -> Confidentieel | C26: Dit betreft informatie die van zo’n grote gevoeligheid is dat openbaarmaking ernstig schadelijk zou zijn. Ongeautoriseerde kennisname moet actief en strikt worden voorkomen. De gevolgen zijn groot: blijvende schade aan vertrouwen in de overheid, aanzienlijke juridische claims en hoge herstelkosten. Op dit niveau gelden altijd aanvullende beveiligingsregels uit Algemene Beveiligingseisen voor Defensieopdrachten (ABDO) of Algemene Beveiligingseisen voor Rijksoverheidsopdrachten (ABRO). BIO2 alleen is niet voldoende, omdat hier nationale veiligheid en staatsbelangen in het geding zijn.
B27: =F3 -> Vertrouwelijk | C27: Bij dit niveau gaat het om informatie die gevoeliger is en waarbij de overheid weerstand tegen spionage en misbruik moet organiseren. Ongeautoriseerde openbaarmaking is schadelijk en moet zoveel mogelijk worden voorkomen. De gevolgen kunnen aanzienlijk zijn: reputatieschade, juridische claims en verstoring van de samenwerking met partners. Bij dit niveau wordt minimaal BIO2 toegepast, aangevuld met risicomanagement en waar nodig extra maatregelen tegen statelijke actoren, zoals monitoring, logging of leveranciersscreening. Dit is ook het niveau waarop de Dep.V-maatregelen uit Algemene Beveiligingseisen voor Defensieopdrachten (ABDO) of Algemene Beveiligingseisen voor Rijksoverheidsopdrachten (ABRO) relevant worden.
B28: =G3 -> Intern | C28: Dit betreft informatie die binnen de organisatie moet blijven, maar waarvan de gevolgen van openbaarmaking nog beperkt zijn. Onbevoegde kennisname is ongewenst, omdat dit hinder kan veroorzaken of herstelwerk nodig maakt. De vertrouwelijkheid is hier vooral een praktische randvoorwaarde: er kan sprake zijn van lichte reputatieschade of interne verstoring, maar de gevolgen zijn doorgaans herstelbaar.
B29: =H3 -> Openbaar | C29: Het gaat hier om informatie die zonder risico gedeeld kan worden met iedereen. De gegevens zijn ongerubriceerd (hoeven niet als zodanig gemarkeerd te worden) en bedoeld voor openbaarheid, bijvoorbeeld op de gemeentelijke website of in een folder. Ongeautoriseerde kennisname is toegestaan en levert geen schade op. Er is dus geen noodzaak om deze informatie extra af te schermen of te beveiligen. Het gaat hierbij om openbare gegevens. De gegevens hoeven niet afgeschermd te worden. Let wel op, deze gegevens kunnen nog steeds integer, authentiek en beschikbaar moeten zijn.

Sheet Resultaat
C2: Resultaat Informatie Classificatietoets BIO2 gemeenten
C4: Datum: | D4: ='Algemene Vragen'!B17 -> <datum uitvoering informatie classificatie> | G4: (inhoud van deze vragen komt van het blad "Algemene vragen")
C5: Invuller: | D5: ='Algemene Vragen'!B11 -> <opsteller baselinetoets>
C6: Organisatie: | D6: ='Algemene Vragen'!B5 -> <organisatienaam>
C7: Afdeling: | D7: ='Algemene Vragen'!B8 -> <afdeling/ bureau/ et cetera>
C8: Proces: | D8: ='Algemene Vragen'!B38 -> <Om welk proces gaat het, wat is het doel?>
C9: Informatie: | D9: ='Algemene Vragen'!B54 -> <Vermeld hier welke gegevens worden verzameld/verwerkt binnen het proces, probeer zo volledig mogelijk te zijn.> Gegevens: • <Bijvoorbeeld financiële gegevens.> Persoonsgegevens: • <Bijvoorbeeld naam, adres en woonplaats, telefoonnummers of postcodes met huisnummers.> Bijzondere persoonsgegevens: • <Bijvoorbeeld burgerservicenummer (BSN), godsdienst of levensovertuiging, ras, politieke gezindheid, medische gegevens, seksuele leven, lidmaatschap van een vakvereniging, strafrechtelijke/ justitiële persoonsgegevens.>
C11: Resultaat informatieclassificatie BIO2
C12: Niveau \ Kwaliteitsaspect | E12: Waarde
C13: Beschikbaarheid | D13: =Beschikbaarheid!D25 -> Niets ingevuld | E13: =Beschikbaarheid!I25 -> De beschikbaarheidsclassificatie is nog niet vastgesteld.
C14: Integriteit | D14: =Integriteit!D20 -> Niets ingevuld | E14: =Integriteit!I20 -> De integriteitsclassificatie is nog niet vastgesteld.
C15: Vertrouwelijkheid | D15: =Vertrouwelijkheid!D22 -> Niets ingevuld | E15: =Vertrouwelijkheid!I21 -> De vertrouwelijkheidsclassificatie is nog niet vastgesteld.
C18: Is er een motivatie om af te wijken van de conclusie (door de data-eigenaar)?
C22: Aldus opgemaakt d.d. | D22: =NOW() -> 46098.964
C25: Naam Eigenaar
C30: Handtekening

Sheet Waarderingstabellen
A1: Tabellen | U1: BIR Basissets
C2: Waarderings en keuze tabellen gebruikt in de overige sheets, niet wijzigen! | O2: Keuze tabellen | U2: basisset 1 integriteit
O3: beschikbaarheid | Q3: Beschikbaar keuze alternatief | V3: Wet en regegeving
Q4: x | V4: Algemeen geldende principes
O5: 0 | V5: Ondersteunende processen
O6: 1
U7: basisset 2 vertrouwelijkheid, persoonsgegevens
V8: Incl Basisset 1
V9: Afhankelijkheden ketens en netwerken
V10: Primaire processen
O11: Keuze tabellen integriteit
O13: 0 | U13: basisset 3 dep-v informatie
O14: 1 | V14: incl Basisset 2
V15: VIR-BI dep V
V16: eu/nato restricted
U18: Basisset 4 | V18: nvt
O20: Keuze tabellen vertrouwelijkheid
O22: 0 | U22: Open info
O23: 1 | U23: geen hoge beschikbaarheids eisen
U24: risicomanagement met baselineset
U25: nato stelt, beleid mbt noodvernietiging
U26: en bcm nato eis
O28: Privacy keuzetabel | Q28: keuzep2 | U28: kritiek versus essentieel systeem vragen
O29: 0 | Q29: ja
O30: 1 | Q30: nee
O31: 2
O32: 3
Q34: Ja
Q35: Nee

Sheet Kladblok
B1: Aantekeningen:
